Workbook

Sheet Cover
B9: American Aerospace Controls
B11: Adjusted EBITDA Analysis
B14: Date | C14: =TODAY() -> 45995
B17: Team Members:
B18: Jack McGoorty | C18: JMcGoorty@kreshmore.com
B20: Color Key
B21: Blue | C21: Indicates Inputs
B22: Green | C22: Indicates values referecing other sheets
B23: Black | C23: Indicates a calculation

Sheet EBITDA Analysis
B1: AAC Adjusted EBITDA Analysis
B2: EBITDA Analysis
B4: EBITDA Analysis | J4: EBITDA Analysis
B5: Per AAC | D5: 44561 | E5: =EOMONTH(D5,12) -> 44926 | F5: =EOMONTH(E5,12) -> 45291 | G5: =EOMONTH(F5,12) -> 45657 | H5: =EOMONTH(G5,9) -> 45930 | J5: Per Kreshmore | L5: 44561 | M5: =EOMONTH(L5,12) -> 44926 | N5: =EOMONTH(M5,12) -> 45291 | O5: =EOMONTH(N5,12) -> 45657 | P5: =EOMONTH(O5,9) -> 45930
B7: Net Income | D7: =EBITDA!D7 -> 119984 | E7: =EBITDA!E7 -> 1556136 | F7: =EBITDA!F7 -> 1000851 | G7: =EBITDA!G7 -> 220635 | H7: =EBITDA!H7 -> 121987 | J7: Net Income | L7: ='Income Statement'!D56 -> 46895.68 | M7: ='Income Statement'!E56 -> -918089.76 | N7: ='Income Statement'!F56 -> 329947.51 | O7: ='Income Statement'!G56 -> 735738.72 | P7: ='Income Statement'!H56 -> -82188.27
C9: Depreciation | D9: =EBITDA!D9 -> 69999 | E9: =EBITDA!E9 -> 78628 | F9: =EBITDA!F9 -> 168273 | G9: =EBITDA!G9 -> 134718 | H9: =EBITDA!H9 -> 17000 | K9: Depreciation | L9: ='Income Statement'!D39+'Income Statement'!D22 -> 5833.33 | M9: ='Income Statement'!E39+'Income Statement'!E22 -> 14461.69 | N9: ='Income Statement'!F39+'Income Statement'!F22 -> 43516.43 | O9: ='Income Statement'!G39+'Income Statement'!G22 -> 109436 | P9: ='Income Statement'!H39+'Income Statement'!H22 -> 375
C10: Interest Expense | D10: =EBITDA!D10 -> 0 | E10: =EBITDA!E10 -> 0 | F10: =EBITDA!F10 -> 13668 | G10: =EBITDA!G10 -> 5890 | H10: =EBITDA!H10 -> 9986 | K10: Interest Expense | L10: =-'Income Statement'!D46 -> 0 | M10: =-'Income Statement'!E46 -> 135.64 | N10: =-'Income Statement'!F46 -> 3878.91 | O10: =-'Income Statement'!G46 -> 240.56 | P10: =-'Income Statement'!H46 -> 724.46
C11: Taxes | D11: =EBITDA!D11 -> 25 | E11: =EBITDA!E11 -> 0 | F11: =EBITDA!F11 -> 30767 | G11: =EBITDA!G11 -> 80165 | H11: =EBITDA!H11 -> 0 | K11: Taxes | L11: ='Income Statement'!D54 -> 0 | M11: ='Income Statement'!E54 -> 166364.31 | N11: ='Income Statement'!F54 -> 26209.75 | O11: ='Income Statement'!G54 -> 6209.75 | P11: ='Income Statement'!H54 -> 0
C12: Fed Employee Tax Credits | D12: =EBITDA!D12 -> -4611 | E12: =EBITDA!E12 -> 0 | F12: =EBITDA!F12 -> 0 | G12: =EBITDA!G12 -> 0 | H12: =EBITDA!H12 -> 0 | K12: Gain/(Loss) on Disposal of Assets | L12: =-'Income Statement'!D48 -> 0 | M12: =-'Income Statement'!E48 -> 0 | N12: =-'Income Statement'!F48 -> 0 | O12: =-'Income Statement'!G48 -> 35311.14 | P12: =-'Income Statement'!H48 -> 0
C13: Investment (income) loss | D13: =EBITDA!D13 -> -23926 | E13: =EBITDA!E13 -> -111926 | F13: =EBITDA!F13 -> -14523 | G13: =EBITDA!G13 -> 17634 | H13: =EBITDA!H13 -> -130431 | K13: Investment (income) loss | L13: =-'Income Statement'!D47 -> -5872.84 | M13: =-'Income Statement'!E47 -> -3448.65 | N13: =-'Income Statement'!F47 -> -3801.01 | O13: =-'Income Statement'!G47 -> -4698.91 | P13: =-'Income Statement'!H47 -> -7147.64
B14: Total Add-Backs | D14: =SUM(D9:D13) -> 41487 | E14: =SUM(E9:E13) -> -33298 | F14: =SUM(F9:F13) -> 198185 | G14: =SUM(G9:G13) -> 238407 | H14: =SUM(H9:H13) -> -103445 | J14: Total Add-Backs | L14: =SUM(L9:L13) -> -39.51 | M14: =SUM(M9:M13) -> 177512.99 | N14: =SUM(N9:N13) -> 69804.08 | O14: =SUM(O9:O13) -> 146498.54 | P14: =SUM(P9:P13) -> -6048.18
B16: Book EBITDA | D16: =D7+D14 -> 161471 | E16: =E7+E14 -> 1522838 | F16: =F7+F14 -> 1199036 | G16: =G7+G14 -> 459042 | H16: =H7+H14 -> 18542 | J16: Book EBITDA | L16: =L7+L14 -> 46856.17 | M16: =M7+M14 -> -740576.77 | N16: =N7+N14 -> 399751.59 | O16: =O7+O14 -> 882237.26 | P16: =P7+P14 -> -88236.45
B18: Adjustments | J18: Adjustments*
C19: Officer's Salary | D19: =EBITDA!D18 -> 355769 | E19: =EBITDA!E18 -> 364361 | F19: =EBITDA!F18 -> 171000 | G19: =EBITDA!G18 -> 100000 | H19: =EBITDA!H18 -> 75000 | K19: Officer's Salary | L19: ='Detailed IS'!F104 -> 31846.15 | M19: ='Detailed IS'!G104 -> 31375.39 | N19: ='Detailed IS'!H104 -> 9615.4 | O19: ='Detailed IS'!I104 -> 8884.63 | P19: ='Detailed IS'!J104 -> 0
C20: Directors Fees | D20: =EBITDA!D19 -> 180693 | E20: =EBITDA!E19 -> 180000 | F20: =EBITDA!F19 -> 224000 | G20: =EBITDA!G19 -> 240000 | H20: =EBITDA!H19 -> 178846 | K20: Directors Fees | L20: ='Detailed IS'!F108 -> 15923.11 | M20: ='Detailed IS'!G108 -> 15230.8 | N20: ='Detailed IS'!H108 -> 19384.64 | O20: ='Detailed IS'!I108 -> 20307.71 | P20: ='Detailed IS'!J108 -> 20307.71
C21: Dennis PA | D21: =EBITDA!D20 -> 15000 | E21: =EBITDA!E20 -> 0 | F21: =EBITDA!F20 -> 0 | G21: =EBITDA!G20 -> 0 | H21: =EBITDA!H20 -> 0 | K21: Dennis PA | L21: =EBITDA!L20 -> 0 | M21: =EBITDA!M20 -> 0 | N21: =EBITDA!N20 -> 0 | O21: =EBITDA!O20 -> 0 | P21: =EBITDA!P20 -> 0
C22: Prof/Cons Fees | D22: =EBITDA!D21 -> 10580 | E22: =EBITDA!E21 -> 28054 | F22: =EBITDA!F21 -> 31288 | G22: =EBITDA!G21 -> 53880 | H22: =EBITDA!H21 -> 86402 | K22: Prof/Cons Fees | L22: ='Detailed IS'!F123+'Detailed IS'!F122 -> 9479.7 | M22: ='Detailed IS'!G123+'Detailed IS'!G122 -> 31472.39 | N22: ='Detailed IS'!H123+'Detailed IS'!H122 -> 17643.54 | O22: ='Detailed IS'!I123+'Detailed IS'!I122 -> 24331.22 | P22: ='Detailed IS'!J123+'Detailed IS'!J122 -> 10911.51
C23: Acctg Fees | D23: =EBITDA!D22 -> 0 | E23: =EBITDA!E22 -> 37000 | F23: =EBITDA!F22 -> 45000 | G23: =EBITDA!G22 -> 0 | H23: =EBITDA!H22 -> 0 | K23: Acctg Fees | L23: ='Detailed IS'!F121 -> 15150 | M23: ='Detailed IS'!G121 -> 4000 | N23: ='Detailed IS'!H121 -> 24935 | O23: ='Detailed IS'!I121 -> -13143 | P23: ='Detailed IS'!J121 -> 0
C24: MFG Variance | D24: =EBITDA!D23 -> 0 | E24: =EBITDA!E23 -> 0 | F24: =EBITDA!F23 -> 0 | G24: =EBITDA!G23 -> -265500 | H24: =EBITDA!H23 -> 265500 | K24: MFG Variance | L24: =EBITDA!L23 -> 0 | M24: =EBITDA!M23 -> 0 | N24: =EBITDA!N23 -> 0 | O24: =EBITDA!O23 -> 0 | P24: =EBITDA!P23 -> 0
C25: Staff Cash Bonuses | D25: =EBITDA!D24 -> 40000 | E25: =EBITDA!E24 -> 40000 | F25: =EBITDA!F24 -> 40000 | G25: =EBITDA!G24 -> 40000 | H25: =EBITDA!H24 -> 40000 | K25: Staff Cash Bonuses | L25: =EBITDA!L24 -> 0 | M25: =EBITDA!M24 -> 0 | N25: =EBITDA!N24 -> 0 | O25: =EBITDA!O24 -> 0 | P25: =EBITDA!P24 -> 0
B26: Total Adjustments | D26: =SUM(D19:D25) -> 602042 | E26: =SUM(E19:E25) -> 649415 | F26: =SUM(F19:F25) -> 511288 | G26: =SUM(G19:G25) -> 168380 | H26: =SUM(H19:H25) -> 645748 | J26: Total Adjustments | L26: =SUM(L19:L25) -> 72398.96 | M26: =SUM(M19:M25) -> 82078.58 | N26: =SUM(N19:N25) -> 71578.58 | O26: =SUM(O19:O25) -> 40380.56 | P26: =SUM(P19:P25) -> 31219.22
B28: Adjusted EBITDA | D28: =D16+D26 -> 763513 | E28: =E16+E26 -> 2172253 | F28: =F16+F26 -> 1710324 | G28: =G16+G26 -> 627422 | H28: =H16+H26 -> 664290 | J28: Adjusted EBITDA | L28: =L16+L26 -> 119255.13 | M28: =M16+M26 -> -658498.19 | N28: =N16+N26 -> 471330.17 | O28: =O16+O26 -> 922617.82 | P28: =P16+P26 -> -57017.23
J30: *Note: Kreshmore did not look for other add-back items

Sheet Financials >>

Sheet Income Statement
B1: AAC Adjusted EBITDA Analysis
B2: Income Statement
B4: American Aerospace Controls | J4: as a % of Revenue
B5: Income Statement | D5: Actual | E5: Actual | F5: Actual | G5: Actual | H5: Actual | J5: Actual | K5: Actual | L5: Actual | M5: Actual | N5: Actual
D6: 44561 | E6: =EOMONTH(D6,12) -> 44926 | F6: =EOMONTH(E6,12) -> 45291 | G6: =EOMONTH(F6,12) -> 45657 | H6: =EOMONTH(G6,9) -> 45930 | J6: 44561 | K6: =EOMONTH(J6,12) -> 44926 | L6: =EOMONTH(K6,12) -> 45291 | M6: =EOMONTH(L6,12) -> 45657 | N6: =EOMONTH(M6,9) -> 45930
B7: Revenue
C8: Product Sales | D8: =SUMIFS('Detailed IS'!F:F,'Detailed IS'!$D:$D,$C8) -> 1125166.1 | E8: =SUMIFS('Detailed IS'!G:G,'Detailed IS'!$D:$D,$C8) -> 515796.36 | F8: =SUMIFS('Detailed IS'!H:H,'Detailed IS'!$D:$D,$C8) -> 1245336.4 | G8: =SUMIFS('Detailed IS'!I:I,'Detailed IS'!$D:$D,$C8) -> 937459.54 | H8: =SUMIFS('Detailed IS'!J:J,'Detailed IS'!$D:$D,$C8) -> 392663.3 | J8: =D8/D$11 -> 0.99383911 | K8: =E8/E$11 -> 0.99901221 | L8: =F8/F$11 -> 0.99560351 | M8: =G8/G$11 -> 0.71897159 | N8: =H8/H$11 -> 0.99923657
C9: Other Income | D9: =SUMIFS('Detailed IS'!F:F,'Detailed IS'!$D:$D,$C9) -> 6975 | E9: =SUMIFS('Detailed IS'!G:G,'Detailed IS'!$D:$D,$C9) -> 510 | F9: =SUMIFS('Detailed IS'!H:H,'Detailed IS'!$D:$D,$C9) -> 5499.29 | G9: =SUMIFS('Detailed IS'!I:I,'Detailed IS'!$D:$D,$C9) -> 2198 | H9: =SUMIFS('Detailed IS'!J:J,'Detailed IS'!$D:$D,$C9) -> 300 | J9: =D9/D$11 -> 0.0061608926 | K9: =E9/E$11 -> 0.00098778562 | L9: =F9/F$11 -> 0.0043964927 | M9: =G9/G$11 -> 0.0016857256 | N9: =H9/H$11 -> 0.00076343007
C10: Engineering Services | D10: =SUMIFS('Detailed IS'!F:F,'Detailed IS'!$D:$D,$C10) -> 0 | E10: =SUMIFS('Detailed IS'!G:G,'Detailed IS'!$D:$D,$C10) -> 0 | F10: =SUMIFS('Detailed IS'!H:H,'Detailed IS'!$D:$D,$C10) -> 0 | G10: =SUMIFS('Detailed IS'!I:I,'Detailed IS'!$D:$D,$C10) -> 364232 | H10: =SUMIFS('Detailed IS'!J:J,'Detailed IS'!$D:$D,$C10) -> 0 | J10: =D10/D$11 -> 0 | K10: =E10/E$11 -> 0 | L10: =F10/F$11 -> 0 | M10: =G10/G$11 -> 0.27934268 | N10: =H10/H$11 -> 0
B11: Total Revenue | D11: =SUM(D8:D10) -> 1132141.1 | E11: =SUM(E8:E10) -> 516306.36 | F11: =SUM(F8:F10) -> 1250835.7 | G11: =SUM(G8:G10) -> 1303889.5 | H11: =SUM(H8:H10) -> 392963.3 | J11: =D11/D$11 -> 1 | K11: =E11/E$11 -> 1 | L11: =F11/F$11 -> 1 | M11: =G11/G$11 -> 1 | N11: =H11/H$11 -> 1
B13: Cost of Goods Sold
C14: Materials | D14: =SUMIFS('Detailed IS'!F:F,'Detailed IS'!$D:$D,$C14) -> 197111.02 | E14: =SUMIFS('Detailed IS'!G:G,'Detailed IS'!$D:$D,$C14) -> 440595.55 | F14: =SUMIFS('Detailed IS'!H:H,'Detailed IS'!$D:$D,$C14) -> 78394.86 | G14: =SUMIFS('Detailed IS'!I:I,'Detailed IS'!$D:$D,$C14) -> -205801.84 | H14: =SUMIFS('Detailed IS'!J:J,'Detailed IS'!$D:$D,$C14) -> 57992.53 | J14: =D14/D$11 -> 0.17410463 | K14: =E14/E$11 -> 0.85336069 | L14: =F14/F$11 -> 0.062673987 | M14: =G14/G$11 -> -0.15783687 | N14: =H14/H$11 -> 0.14757747
C15: Salaries and Wages - Direct | D15: =SUMIFS('Detailed IS'!F:F,'Detailed IS'!$D:$D,$C15) -> 271970.64 | E15: =SUMIFS('Detailed IS'!G:G,'Detailed IS'!$D:$D,$C15) -> 260468.73 | F15: =SUMIFS('Detailed IS'!H:H,'Detailed IS'!$D:$D,$C15) -> 272225.94 | G15: =SUMIFS('Detailed IS'!I:I,'Detailed IS'!$D:$D,$C15) -> 270315.94 | H15: =SUMIFS('Detailed IS'!J:J,'Detailed IS'!$D:$D,$C15) -> 238865.16 | J15: =D15/D$11 -> 0.2402268 | K15: =E15/E$11 -> 0.50448484 | L15: =F15/F$11 -> 0.21763525 | M15: =G15/G$11 -> 0.20731506 | N15: =H15/H$11 -> 0.60785615
C16: Overhead | D16: =SUMIFS('Detailed IS'!F:F,'Detailed IS'!$D:$D,$C16) -> -4331.7 | E16: =SUMIFS('Detailed IS'!G:G,'Detailed IS'!$D:$D,$C16) -> 21913.42 | F16: =SUMIFS('Detailed IS'!H:H,'Detailed IS'!$D:$D,$C16) -> 50427.7 | G16: =SUMIFS('Detailed IS'!I:I,'Detailed IS'!$D:$D,$C16) -> -30164 | H16: =SUMIFS('Detailed IS'!J:J,'Detailed IS'!$D:$D,$C16) -> -70770.26 | J16: =D16/D$11 -> -0.003826113 | K16: =E16/E$11 -> 0.042442669 | L16: =F16/F$11 -> 0.040315207 | M16: =G16/G$11 -> -0.023133861 | N16: =H16/H$11 -> -0.18009382
C17: Outside Services | D17: =SUMIFS('Detailed IS'!F:F,'Detailed IS'!$D:$D,$C17) -> 13578.35 | E17: =SUMIFS('Detailed IS'!G:G,'Detailed IS'!$D:$D,$C17) -> 6833.06 | F17: =SUMIFS('Detailed IS'!H:H,'Detailed IS'!$D:$D,$C17) -> 22493.41 | G17: =SUMIFS('Detailed IS'!I:I,'Detailed IS'!$D:$D,$C17) -> 9512.15 | H17: =SUMIFS('Detailed IS'!J:J,'Detailed IS'!$D:$D,$C17) -> 16237.04 | J17: =D17/D$11 -> 0.011993513 | K17: =E17/E$11 -> 0.013234507 | L17: =F17/F$11 -> 0.017982706 | M17: =G17/G$11 -> 0.0072952115 | N17: =H17/H$11 -> 0.041319482
C18: Other COGs | D18: =SUMIFS('Detailed IS'!F:F,'Detailed IS'!$D:$D,$C18) -> 29942.33 | E18: =SUMIFS('Detailed IS'!G:G,'Detailed IS'!$D:$D,$C18) -> 15588.64 | F18: =SUMIFS('Detailed IS'!H:H,'Detailed IS'!$D:$D,$C18) -> -11281.36 | G18: =SUMIFS('Detailed IS'!I:I,'Detailed IS'!$D:$D,$C18) -> 59598.5 | H18: =SUMIFS('Detailed IS'!J:J,'Detailed IS'!$D:$D,$C18) -> 24568.06 | J18: =D18/D$11 -> 0.026447524 | K18: =E18/E$11 -> 0.030192617 | L18: =F18/F$11 -> -0.0090190583 | M18: =G18/G$11 -> 0.045708243 | N18: =H18/H$11 -> 0.062519986
C19: MFG Variance | D19: =SUMIFS('Detailed IS'!F:F,'Detailed IS'!$D:$D,$C19) -> 42577.59 | E19: =SUMIFS('Detailed IS'!G:G,'Detailed IS'!$D:$D,$C19) -> -232.1 | F19: =SUMIFS('Detailed IS'!H:H,'Detailed IS'!$D:$D,$C19) -> 1416.88 | G19: =SUMIFS('Detailed IS'!I:I,'Detailed IS'!$D:$D,$C19) -> 670.34 | H19: =SUMIFS('Detailed IS'!J:J,'Detailed IS'!$D:$D,$C19) -> 22291.02 | J19: =D19/D$11 -> 0.037608023 | K19: =E19/E$11 -> -0.0004495393 | L19: =F19/F$11 -> 0.0011327467 | M19: =G19/G$11 -> 0.00051410797 | N19: =H19/H$11 -> 0.05672545
C20: Freight | D20: =SUMIFS('Detailed IS'!F:F,'Detailed IS'!$D:$D,$C20) -> 6917.18 | E20: =SUMIFS('Detailed IS'!G:G,'Detailed IS'!$D:$D,$C20) -> 3219.95 | F20: =SUMIFS('Detailed IS'!H:H,'Detailed IS'!$D:$D,$C20) -> 2284.07 | G20: =SUMIFS('Detailed IS'!I:I,'Detailed IS'!$D:$D,$C20) -> 4374.26 | H20: =SUMIFS('Detailed IS'!J:J,'Detailed IS'!$D:$D,$C20) -> 6552.37 | J20: =D20/D$11 -> 0.0061098212 | K20: =E20/E$11 -> 0.0062365104 | L20: =F20/F$11 -> 0.0018260352 | M20: =G20/G$11 -> 0.003354778 | N20: =H20/H$11 -> 0.016674254
C21: Building Expenses - Direct | D21: =SUMIFS('Detailed IS'!F:F,'Detailed IS'!$D:$D,$C21) -> 25208.55 | E21: =SUMIFS('Detailed IS'!G:G,'Detailed IS'!$D:$D,$C21) -> 14822.71 | F21: =SUMIFS('Detailed IS'!H:H,'Detailed IS'!$D:$D,$C21) -> 16294.2 | G21: =SUMIFS('Detailed IS'!I:I,'Detailed IS'!$D:$D,$C21) -> 17015.01 | H21: =SUMIFS('Detailed IS'!J:J,'Detailed IS'!$D:$D,$C21) -> 18536.48 | J21: =D21/D$11 -> 0.022266261 | K21: =E21/E$11 -> 0.028709137 | L21: =F21/F$11 -> 0.013026651 | M21: =G21/G$11 -> 0.013049426 | N21: =H21/H$11 -> 0.047171021
C22: Depreciation & Amortization - Direct | D22: =SUMIFS('Detailed IS'!F:F,'Detailed IS'!$D:$D,$C22) -> 4958.33 | E22: =SUMIFS('Detailed IS'!G:G,'Detailed IS'!$D:$D,$C22) -> 12292.44 | F22: =SUMIFS('Detailed IS'!H:H,'Detailed IS'!$D:$D,$C22) -> 42385.13 | G22: =SUMIFS('Detailed IS'!I:I,'Detailed IS'!$D:$D,$C22) -> 93020.6 | H22: =SUMIFS('Detailed IS'!J:J,'Detailed IS'!$D:$D,$C22) -> 375 | J22: =D22/D$11 -> 0.0043796041 | K22: =E22/E$11 -> 0.023808423 | L22: =F22/F$11 -> 0.03388545 | M22: =G22/G$11 -> 0.071340859 | N22: =H22/H$11 -> 0.00095428759
B23: Total Cost of Goods Sold | D23: =SUM(D14:D22) -> 587932.29 | E23: =SUM(E14:E22) -> 775502.4 | F23: =SUM(F14:F22) -> 474640.83 | G23: =SUM(G14:G22) -> 218540.96 | H23: =SUM(H14:H22) -> 314647.4 | J23: =D23/D$11 -> 0.51931006 | K23: =E23/E$11 -> 1.5020198 | L23: =F23/F$11 -> 0.37945898 | M23: =G23/G$11 -> 0.16760696 | N23: =H23/H$11 -> 0.80070429
B25: Gross Profit | D25: =D11-D23 -> 544208.86 | E25: =E11-E23 -> -259196.04 | F25: =F11-F23 -> 776194.86 | G25: =G11-G23 -> 1085348.6 | H25: =H11-H23 -> 78315.9 | J25: =D25/D$11 -> 0.48068994 | K25: =E25/E$11 -> -0.50201985 | L25: =F25/F$11 -> 0.62054102 | M25: =G25/G$11 -> 0.83239304 | N25: =H25/H$11 -> 0.19929571
B27: SG&A Expenses
C28: Salaries & Wages | D28: =SUMIFS('Detailed IS'!F:F,'Detailed IS'!$D:$D,$C28) -> 114955.85 | E28: =SUMIFS('Detailed IS'!G:G,'Detailed IS'!$D:$D,$C28) -> 166624.8 | F28: =SUMIFS('Detailed IS'!H:H,'Detailed IS'!$D:$D,$C28) -> 93718.26 | G28: =SUMIFS('Detailed IS'!I:I,'Detailed IS'!$D:$D,$C28) -> 105528.13 | H28: =SUMIFS('Detailed IS'!J:J,'Detailed IS'!$D:$D,$C28) -> 101135.73 | J28: =D28/D$11 -> 0.10153844 | K28: =E28/E$11 -> 0.32272467 | L28: =F28/F$11 -> 0.074924517 | M28: =G28/G$11 -> 0.080933336 | N28: =H28/H$11 -> 0.25736686
C29: Sales & Marketing | D29: =SUMIFS('Detailed IS'!F:F,'Detailed IS'!$D:$D,$C29) -> 24421.28 | E29: =SUMIFS('Detailed IS'!G:G,'Detailed IS'!$D:$D,$C29) -> 37034.35 | F29: =SUMIFS('Detailed IS'!H:H,'Detailed IS'!$D:$D,$C29) -> 7442.57 | G29: =SUMIFS('Detailed IS'!I:I,'Detailed IS'!$D:$D,$C29) -> 28874.28 | H29: =SUMIFS('Detailed IS'!J:J,'Detailed IS'!$D:$D,$C29) -> 29451.06 | J29: =D29/D$11 -> 0.021570879 | K29: =E29/E$11 -> 0.071729409 | L29: =F29/F$11 -> 0.0059500781 | M29: =G29/G$11 -> 0.022144729 | N29: =H29/H$11 -> 0.074946083
C30: Directors Fees | D30: =SUMIFS('Detailed IS'!F:F,'Detailed IS'!$D:$D,$C30) -> 15923.11 | E30: =SUMIFS('Detailed IS'!G:G,'Detailed IS'!$D:$D,$C30) -> 15230.8 | F30: =SUMIFS('Detailed IS'!H:H,'Detailed IS'!$D:$D,$C30) -> 19384.64 | G30: =SUMIFS('Detailed IS'!I:I,'Detailed IS'!$D:$D,$C30) -> 20307.71 | H30: =SUMIFS('Detailed IS'!J:J,'Detailed IS'!$D:$D,$C30) -> 20307.71 | J30: =D30/D$11 -> 0.014064598 | K30: =E30/E$11 -> 0.02949954 | L30: =F30/F$11 -> 0.015497351 | M30: =G30/G$11 -> 0.015574717 | N30: =H30/H$11 -> 0.051678388
C31: Other Expenses | D31: =SUMIFS('Detailed IS'!F:F,'Detailed IS'!$D:$D,$C31) -> 12242.28 | E31: =SUMIFS('Detailed IS'!G:G,'Detailed IS'!$D:$D,$C31) -> 38020.75 | F31: =SUMIFS('Detailed IS'!H:H,'Detailed IS'!$D:$D,$C31) -> 13384.12 | G31: =SUMIFS('Detailed IS'!I:I,'Detailed IS'!$D:$D,$C31) -> 3535.94 | H31: =SUMIFS('Detailed IS'!J:J,'Detailed IS'!$D:$D,$C31) -> 597.67 | J31: =D31/D$11 -> 0.010813387 | K31: =E31/E$11 -> 0.073639902 | L31: =F31/F$11 -> 0.010700142 | M31: =G31/G$11 -> 0.0027118401 | N31: =H31/H$11 -> 0.0015209308
C32: Professional Fees | D32: =SUMIFS('Detailed IS'!F:F,'Detailed IS'!$D:$D,$C32) -> 24629.7 | E32: =SUMIFS('Detailed IS'!G:G,'Detailed IS'!$D:$D,$C32) -> 35472.39 | F32: =SUMIFS('Detailed IS'!H:H,'Detailed IS'!$D:$D,$C32) -> 42578.54 | G32: =SUMIFS('Detailed IS'!I:I,'Detailed IS'!$D:$D,$C32) -> 11188.22 | H32: =SUMIFS('Detailed IS'!J:J,'Detailed IS'!$D:$D,$C32) -> 10911.51 | J32: =D32/D$11 -> 0.021754973 | K32: =E32/E$11 -> 0.068704151 | L32: =F32/F$11 -> 0.034040074 | M32: =G32/G$11 -> 0.0085806502 | N32: =H32/H$11 -> 0.02776725
C33: Human Resources & Trianing Expenses | D33: =SUMIFS('Detailed IS'!F:F,'Detailed IS'!$D:$D,$C33) -> 40323 | E33: =SUMIFS('Detailed IS'!G:G,'Detailed IS'!$D:$D,$C33) -> 45000 | F33: =SUMIFS('Detailed IS'!H:H,'Detailed IS'!$D:$D,$C33) -> 40000 | G33: =SUMIFS('Detailed IS'!I:I,'Detailed IS'!$D:$D,$C33) -> 40708.77 | H33: =SUMIFS('Detailed IS'!J:J,'Detailed IS'!$D:$D,$C33) -> 1192.02 | J33: =D33/D$11 -> 0.035616584 | K33: =E33/E$11 -> 0.087157555 | L33: =F33/F$11 -> 0.031978621 | M33: =G33/G$11 -> 0.031221027 | N33: =H33/H$11 -> 0.003033413
C34: Office Expense | D34: =SUMIFS('Detailed IS'!F:F,'Detailed IS'!$D:$D,$C34) -> 7710.08 | E34: =SUMIFS('Detailed IS'!G:G,'Detailed IS'!$D:$D,$C34) -> 9456.74 | F34: =SUMIFS('Detailed IS'!H:H,'Detailed IS'!$D:$D,$C34) -> 18443.85 | G34: =SUMIFS('Detailed IS'!I:I,'Detailed IS'!$D:$D,$C34) -> 34152.84 | H34: =SUMIFS('Detailed IS'!J:J,'Detailed IS'!$D:$D,$C34) -> 2366.91 | J34: =D34/D$11 -> 0.0068101756 | K34: =E34/E$11 -> 0.018316141 | L34: =F34/F$11 -> 0.014745222 | M34: =G34/G$11 -> 0.026193047 | N34: =H34/H$11 -> 0.0060232342
C35: Charity | D35: =SUMIFS('Detailed IS'!F:F,'Detailed IS'!$D:$D,$C35) -> 3025 | E35: =SUMIFS('Detailed IS'!G:G,'Detailed IS'!$D:$D,$C35) -> 300 | F35: =SUMIFS('Detailed IS'!H:H,'Detailed IS'!$D:$D,$C35) -> 1625 | G35: =SUMIFS('Detailed IS'!I:I,'Detailed IS'!$D:$D,$C35) -> 1675 | H35: =SUMIFS('Detailed IS'!J:J,'Detailed IS'!$D:$D,$C35) -> 300 | J35: =D35/D$11 -> 0.0026719283 | K35: =E35/E$11 -> 0.00058105037 | L35: =F35/F$11 -> 0.0012991315 | M35: =G35/G$11 -> 0.001284618 | N35: =H35/H$11 -> 0.00076343007
C36: Bank Charges | D36: =SUMIFS('Detailed IS'!F:F,'Detailed IS'!$D:$D,$C36) -> 1610.05 | E36: =SUMIFS('Detailed IS'!G:G,'Detailed IS'!$D:$D,$C36) -> 534.41 | F36: =SUMIFS('Detailed IS'!H:H,'Detailed IS'!$D:$D,$C36) -> 2384.29 | G36: =SUMIFS('Detailed IS'!I:I,'Detailed IS'!$D:$D,$C36) -> 2117.34 | H36: =SUMIFS('Detailed IS'!J:J,'Detailed IS'!$D:$D,$C36) -> 1501.51 | J36: =D36/D$11 -> 0.0014221283 | K36: =E36/E$11 -> 0.0010350638 | L36: =F36/F$11 -> 0.0019061576 | M36: =G36/G$11 -> 0.0016238645 | N36: =H36/H$11 -> 0.003820993
C37: Building Expenses | D37: =SUMIFS('Detailed IS'!F:F,'Detailed IS'!$D:$D,$C37) -> 8051.32 | E37: =SUMIFS('Detailed IS'!G:G,'Detailed IS'!$D:$D,$C37) -> 5129.33 | F37: =SUMIFS('Detailed IS'!H:H,'Detailed IS'!$D:$D,$C37) -> 5276.24 | G37: =SUMIFS('Detailed IS'!I:I,'Detailed IS'!$D:$D,$C37) -> -960.21 | H37: =SUMIFS('Detailed IS'!J:J,'Detailed IS'!$D:$D,$C37) -> 0 | J37: =D37/D$11 -> 0.0071115867 | K37: =E37/E$11 -> 0.0099346636 | L37: =F37/F$11 -> 0.0042181719 | M37: =G37/G$11 -> -0.00073641974 | N37: =H37/H$11 -> 0
C38: Profit Sharing | D38: =SUMIFS('Detailed IS'!F:F,'Detailed IS'!$D:$D,$C38) -> 250000 | E38: =SUMIFS('Detailed IS'!G:G,'Detailed IS'!$D:$D,$C38) -> 150000 | F38: =SUMIFS('Detailed IS'!H:H,'Detailed IS'!$D:$D,$C38) -> 175000 | G38: =SUMIFS('Detailed IS'!I:I,'Detailed IS'!$D:$D,$C38) -> 50000 | H38: =SUMIFS('Detailed IS'!J:J,'Detailed IS'!$D:$D,$C38) -> 0 | J38: =D38/D$11 -> 0.22082052 | K38: =E38/E$11 -> 0.29052518 | L38: =F38/F$11 -> 0.13990647 | M38: =G38/G$11 -> 0.038346807 | N38: =H38/H$11 -> 0
C39: Depreciation & Amortization | D39: =SUMIFS('Detailed IS'!F:F,'Detailed IS'!$D:$D,$C39) -> 875 | E39: =SUMIFS('Detailed IS'!G:G,'Detailed IS'!$D:$D,$C39) -> 2169.25 | F39: =SUMIFS('Detailed IS'!H:H,'Detailed IS'!$D:$D,$C39) -> 1131.3 | G39: =SUMIFS('Detailed IS'!I:I,'Detailed IS'!$D:$D,$C39) -> 16415.4 | H39: =SUMIFS('Detailed IS'!J:J,'Detailed IS'!$D:$D,$C39) -> 0 | J39: =D39/D$11 -> 0.00077287183 | K39: =E39/E$11 -> 0.0042014784 | L39: =F39/F$11 -> 0.00090443534 | M39: =G39/G$11 -> 0.012589563 | N39: =H39/H$11 -> 0
B40: Total SG&A Expenses | D40: =SUM(D28:D39) -> 503766.67 | E40: =SUM(E28:E39) -> 504972.82 | F40: =SUM(F28:F39) -> 420368.81 | G40: =SUM(G28:G39) -> 313543.42 | H40: =SUM(H28:H39) -> 167764.12 | J40: =D40/D$11 -> 0.44496808 | K40: =E40/E$11 -> 0.97804881 | L40: =F40/F$11 -> 0.33607037 | M40: =G40/G$11 -> 0.24046778 | N40: =H40/H$11 -> 0.42692058
B42: Net Operating Income | D42: =D25-D40 -> 40442.19 | E42: =E25-E40 -> -764168.86 | F42: =F25-F40 -> 355826.05 | G42: =G25-G40 -> 771805.16 | H42: =H25-H40 -> -89448.22 | J42: =D42/D$11 -> 0.035721862 | K42: =E42/E$11 -> -1.4800687 | L42: =F42/F$11 -> 0.28447066 | M42: =G42/G$11 -> 0.59192526 | N42: =H42/H$11 -> -0.22762487
J43: =D43/D$11 -> 0 | K43: =E43/E$11 -> 0 | L43: =F43/F$11 -> 0 | M43: =G43/G$11 -> 0 | N43: =H43/H$11 -> 0
B44: Other Income (Expenses) | J44: =D44/D$11 -> 0 | K44: =E44/E$11 -> 0 | L44: =F44/F$11 -> 0 | M44: =G44/G$11 -> 0 | N44: =H44/H$11 -> 0
C45: Interest Income | D45: =SUMIFS('Detailed IS'!F:F,'Detailed IS'!$D:$D,$C45) -> 0.96 | E45: =SUMIFS('Detailed IS'!G:G,'Detailed IS'!$D:$D,$C45) -> 0 | F45: =SUMIFS('Detailed IS'!H:H,'Detailed IS'!$D:$D,$C45) -> 0 | G45: =SUMIFS('Detailed IS'!I:I,'Detailed IS'!$D:$D,$C45) -> 0.72 | H45: =SUMIFS('Detailed IS'!J:J,'Detailed IS'!$D:$D,$C45) -> 0.02 | J45: =D45/D$11 -> 8.4795081e-07 | K45: =E45/E$11 -> 0 | L45: =F45/F$11 -> 0 | M45: =G45/G$11 -> 5.5219401e-07 | N45: =H45/H$11 -> 5.0895338e-08
...

Sheet Balance Sheet
B1: AAC Adjusted EBITDA Analysis
B2: Balance Sheet
B4: American Aerospace Controls
B5: Balance Sheet | D5: Actual | E5: Actual | F5: Actual | G5: Actual | H5: Actual
B6: As of | D6: 44561 | E6: =EOMONTH(D6,12) -> 44926 | F6: =EOMONTH(E6,12) -> 45291 | G6: =EOMONTH(F6,12) -> 45657 | H6: =EOMONTH(G6,9) -> 45930
B7: Assets
B8: Current Assets
C9: Cash | D9: =SUMIFS('Detailed BS'!F:F,'Detailed BS'!$D:$D,$C9) -> 1199208 | E9: =SUMIFS('Detailed BS'!G:G,'Detailed BS'!$D:$D,$C9) -> 2398756.5 | F9: =SUMIFS('Detailed BS'!H:H,'Detailed BS'!$D:$D,$C9) -> 1615267.5 | G9: =SUMIFS('Detailed BS'!I:I,'Detailed BS'!$D:$D,$C9) -> 1026698.9 | H9: =SUMIFS('Detailed BS'!J:J,'Detailed BS'!$D:$D,$C9) -> 580318.35
C10: Accounts Receivable | D10: =SUMIFS('Detailed BS'!F:F,'Detailed BS'!$D:$D,$C10) -> 1105726.3 | E10: =SUMIFS('Detailed BS'!G:G,'Detailed BS'!$D:$D,$C10) -> 525775.94 | F10: =SUMIFS('Detailed BS'!H:H,'Detailed BS'!$D:$D,$C10) -> 1262808.8 | G10: =SUMIFS('Detailed BS'!I:I,'Detailed BS'!$D:$D,$C10) -> 1147802.6 | H10: =SUMIFS('Detailed BS'!J:J,'Detailed BS'!$D:$D,$C10) -> 437988.79
C11: Allowance for Doubtful Accounts | D11: =SUMIFS('Detailed BS'!F:F,'Detailed BS'!$D:$D,$C11) -> -15130.57 | E11: =SUMIFS('Detailed BS'!G:G,'Detailed BS'!$D:$D,$C11) -> -15130.57 | F11: =SUMIFS('Detailed BS'!H:H,'Detailed BS'!$D:$D,$C11) -> -15130.57 | G11: =SUMIFS('Detailed BS'!I:I,'Detailed BS'!$D:$D,$C11) -> -15130.57 | H11: =SUMIFS('Detailed BS'!J:J,'Detailed BS'!$D:$D,$C11) -> -15130.57
C12: Customer Depsits | D12: =SUMIFS('Detailed BS'!F:F,'Detailed BS'!$D:$D,$C12) -> -24542.41 | E12: =SUMIFS('Detailed BS'!G:G,'Detailed BS'!$D:$D,$C12) -> -18599.3 | F12: =SUMIFS('Detailed BS'!H:H,'Detailed BS'!$D:$D,$C12) -> -28159.91 | G12: =SUMIFS('Detailed BS'!I:I,'Detailed BS'!$D:$D,$C12) -> -31574.74 | H12: =SUMIFS('Detailed BS'!J:J,'Detailed BS'!$D:$D,$C12) -> -19542.76
C13: Investments | D13: =SUMIFS('Detailed BS'!F:F,'Detailed BS'!$D:$D,$C13) -> 585157.33 | E13: =SUMIFS('Detailed BS'!G:G,'Detailed BS'!$D:$D,$C13) -> 405784.26 | F13: =SUMIFS('Detailed BS'!H:H,'Detailed BS'!$D:$D,$C13) -> 420307.73 | G13: =SUMIFS('Detailed BS'!I:I,'Detailed BS'!$D:$D,$C13) -> 815111.44 | H13: =SUMIFS('Detailed BS'!J:J,'Detailed BS'!$D:$D,$C13) -> 1723864.4
C14: Inventory | D14: =SUMIFS('Detailed BS'!F:F,'Detailed BS'!$D:$D,$C14) -> 2081585 | E14: =SUMIFS('Detailed BS'!G:G,'Detailed BS'!$D:$D,$C14) -> 1935775.6 | F14: =SUMIFS('Detailed BS'!H:H,'Detailed BS'!$D:$D,$C14) -> 2102234.8 | G14: =SUMIFS('Detailed BS'!I:I,'Detailed BS'!$D:$D,$C14) -> 2655768 | H14: =SUMIFS('Detailed BS'!J:J,'Detailed BS'!$D:$D,$C14) -> 2922283.8
C15: Prepaid Expenses | D15: =SUMIFS('Detailed BS'!F:F,'Detailed BS'!$D:$D,$C15) -> 83628.36 | E15: =SUMIFS('Detailed BS'!G:G,'Detailed BS'!$D:$D,$C15) -> 51113.57 | F15: =SUMIFS('Detailed BS'!H:H,'Detailed BS'!$D:$D,$C15) -> 94379.15 | G15: =SUMIFS('Detailed BS'!I:I,'Detailed BS'!$D:$D,$C15) -> 56427.01 | H15: =SUMIFS('Detailed BS'!J:J,'Detailed BS'!$D:$D,$C15) -> 36704.78
B16: Total Current Assets | D16: =SUM(D9:D15) -> 5015632 | E16: =SUM(E9:E15) -> 5283476 | F16: =SUM(F9:F15) -> 5451707.5 | G16: =SUM(G9:G15) -> 5655102.7 | H16: =SUM(H9:H15) -> 5666486.8
B18: Fixed Assets
C19: Land | D19: =SUMIFS('Detailed BS'!F:F,'Detailed BS'!$D:$D,$C19) -> 122000 | E19: =SUMIFS('Detailed BS'!G:G,'Detailed BS'!$D:$D,$C19) -> 122000 | F19: =SUMIFS('Detailed BS'!H:H,'Detailed BS'!$D:$D,$C19) -> 122000 | G19: =SUMIFS('Detailed BS'!I:I,'Detailed BS'!$D:$D,$C19) -> 122000 | H19: =SUMIFS('Detailed BS'!J:J,'Detailed BS'!$D:$D,$C19) -> 122000
C20: Building | D20: =SUMIFS('Detailed BS'!F:F,'Detailed BS'!$D:$D,$C20) -> 1039840.7 | E20: =SUMIFS('Detailed BS'!G:G,'Detailed BS'!$D:$D,$C20) -> 1039840.7 | F20: =SUMIFS('Detailed BS'!H:H,'Detailed BS'!$D:$D,$C20) -> 1039840.7 | G20: =SUMIFS('Detailed BS'!I:I,'Detailed BS'!$D:$D,$C20) -> 1039840.7 | H20: =SUMIFS('Detailed BS'!J:J,'Detailed BS'!$D:$D,$C20) -> 1039840.7
C21: Leasehold Improvements | D21: =SUMIFS('Detailed BS'!F:F,'Detailed BS'!$D:$D,$C21) -> 230619.89 | E21: =SUMIFS('Detailed BS'!G:G,'Detailed BS'!$D:$D,$C21) -> 230619.89 | F21: =SUMIFS('Detailed BS'!H:H,'Detailed BS'!$D:$D,$C21) -> 230619.89 | G21: =SUMIFS('Detailed BS'!I:I,'Detailed BS'!$D:$D,$C21) -> 270383.64 | H21: =SUMIFS('Detailed BS'!J:J,'Detailed BS'!$D:$D,$C21) -> 270383.64
C22: Machinery & Equipment | D22: =SUMIFS('Detailed BS'!F:F,'Detailed BS'!$D:$D,$C22) -> 1849633.8 | E22: =SUMIFS('Detailed BS'!G:G,'Detailed BS'!$D:$D,$C22) -> 2015708.6 | F22: =SUMIFS('Detailed BS'!H:H,'Detailed BS'!$D:$D,$C22) -> 2156400.1 | G22: =SUMIFS('Detailed BS'!I:I,'Detailed BS'!$D:$D,$C22) -> 2162584.7 | H22: =SUMIFS('Detailed BS'!J:J,'Detailed BS'!$D:$D,$C22) -> 2162584.7
C23: Computer Equipment | D23: =SUMIFS('Detailed BS'!F:F,'Detailed BS'!$D:$D,$C23) -> 0 | E23: =SUMIFS('Detailed BS'!G:G,'Detailed BS'!$D:$D,$C23) -> 0 | F23: =SUMIFS('Detailed BS'!H:H,'Detailed BS'!$D:$D,$C23) -> 0 | G23: =SUMIFS('Detailed BS'!I:I,'Detailed BS'!$D:$D,$C23) -> 61187.02 | H23: =SUMIFS('Detailed BS'!J:J,'Detailed BS'!$D:$D,$C23) -> 61187.02
C24: Computer Software | D24: =SUMIFS('Detailed BS'!F:F,'Detailed BS'!$D:$D,$C24) -> 96925.38 | E24: =SUMIFS('Detailed BS'!G:G,'Detailed BS'!$D:$D,$C24) -> 96925.38 | F24: =SUMIFS('Detailed BS'!H:H,'Detailed BS'!$D:$D,$C24) -> 96925.38 | G24: =SUMIFS('Detailed BS'!I:I,'Detailed BS'!$D:$D,$C24) -> 96925.38 | H24: =SUMIFS('Detailed BS'!J:J,'Detailed BS'!$D:$D,$C24) -> 96925.38
C25: Automobiles | D25: =SUMIFS('Detailed BS'!F:F,'Detailed BS'!$D:$D,$C25) -> 110411.14 | E25: =SUMIFS('Detailed BS'!G:G,'Detailed BS'!$D:$D,$C25) -> 110411.14 | F25: =SUMIFS('Detailed BS'!H:H,'Detailed BS'!$D:$D,$C25) -> 110411.14 | G25: =SUMIFS('Detailed BS'!I:I,'Detailed BS'!$D:$D,$C25) -> 0 | H25: =SUMIFS('Detailed BS'!J:J,'Detailed BS'!$D:$D,$C25) -> 0
C26: Accumulated Depreciation | D26: =SUMIFS('Detailed BS'!F:F,'Detailed BS'!$D:$D,$C26) -> -3143237.1 | E26: =SUMIFS('Detailed BS'!G:G,'Detailed BS'!$D:$D,$C26) -> -3221865.5 | F26: =SUMIFS('Detailed BS'!H:H,'Detailed BS'!$D:$D,$C26) -> -3262811 | G26: =SUMIFS('Detailed BS'!I:I,'Detailed BS'!$D:$D,$C26) -> -3322429 | H26: =SUMIFS('Detailed BS'!J:J,'Detailed BS'!$D:$D,$C26) -> -3344929
C27: Accumulated Amortization | D27: =SUMIFS('Detailed BS'!F:F,'Detailed BS'!$D:$D,$C27) -> -96925.38 | E27: =SUMIFS('Detailed BS'!G:G,'Detailed BS'!$D:$D,$C27) -> -96925.38 | F27: =SUMIFS('Detailed BS'!H:H,'Detailed BS'!$D:$D,$C27) -> -96925.38 | G27: =SUMIFS('Detailed BS'!I:I,'Detailed BS'!$D:$D,$C27) -> -96925.38 | H27: =SUMIFS('Detailed BS'!J:J,'Detailed BS'!$D:$D,$C27) -> -96925.38
B28: Total Fixed Assets | D28: =SUM(D19:D27) -> 209268.38 | E28: =SUM(E19:E27) -> 296714.88 | F28: =SUM(F19:F27) -> 396460.82 | G28: =SUM(G19:G27) -> 333567.05 | H28: =SUM(H19:H27) -> 311067.05
B30: Total Assets | D30: =D28+D16 -> 5224900.4 | E30: =E28+E16 -> 5580190.9 | F30: =F28+F16 -> 5848168.3 | G30: =G28+G16 -> 5988669.7 | H30: =H28+H16 -> 5977553.8
B32: Liabilites & Equity
B33: Current Liabilities
C34: Accounts Payable | D34: =SUMIFS('Detailed BS'!F:F,'Detailed BS'!$D:$D,$C34) -> 34422.94 | E34: =SUMIFS('Detailed BS'!G:G,'Detailed BS'!$D:$D,$C34) -> 198880.72 | F34: =SUMIFS('Detailed BS'!H:H,'Detailed BS'!$D:$D,$C34) -> 176183.42 | G34: =SUMIFS('Detailed BS'!I:I,'Detailed BS'!$D:$D,$C34) -> 115586.41 | H34: =SUMIFS('Detailed BS'!J:J,'Detailed BS'!$D:$D,$C34) -> 78017.62
C35: Accured Expenses | D35: =SUMIFS('Detailed BS'!F:F,'Detailed BS'!$D:$D,$C35) -> 220208.63 | E35: =SUMIFS('Detailed BS'!G:G,'Detailed BS'!$D:$D,$C35) -> 267425.5 | F35: =SUMIFS('Detailed BS'!H:H,'Detailed BS'!$D:$D,$C35) -> 288664.96 | G35: =SUMIFS('Detailed BS'!I:I,'Detailed BS'!$D:$D,$C35) -> 205684.8 | H35: =SUMIFS('Detailed BS'!J:J,'Detailed BS'!$D:$D,$C35) -> 123292.21
C36: Leases Payable | D36: =SUMIFS('Detailed BS'!F:F,'Detailed BS'!$D:$D,$C36) -> 0 | E36: =SUMIFS('Detailed BS'!G:G,'Detailed BS'!$D:$D,$C36) -> 141531.06 | F36: =SUMIFS('Detailed BS'!H:H,'Detailed BS'!$D:$D,$C36) -> 178423.59 | G36: =SUMIFS('Detailed BS'!I:I,'Detailed BS'!$D:$D,$C36) -> 116507.76 | H36: =SUMIFS('Detailed BS'!J:J,'Detailed BS'!$D:$D,$C36) -> 66348.67
B37: Total Current Liabilites | D37: =SUM(D34:D36) -> 254631.57 | E37: =SUM(E34:E36) -> 607837.28 | F37: =SUM(F34:F36) -> 643271.97 | G37: =SUM(G34:G36) -> 437778.97 | H37: =SUM(H34:H36) -> 267658.5
B39: Equity
C40: Common Stock | D40: =SUMIFS('Detailed BS'!F:F,'Detailed BS'!$D:$D,$C40) -> 165000 | E40: =SUMIFS('Detailed BS'!G:G,'Detailed BS'!$D:$D,$C40) -> 165000 | F40: =SUMIFS('Detailed BS'!H:H,'Detailed BS'!$D:$D,$C40) -> 165000 | G40: =SUMIFS('Detailed BS'!I:I,'Detailed BS'!$D:$D,$C40) -> 165000 | H40: =SUMIFS('Detailed BS'!J:J,'Detailed BS'!$D:$D,$C40) -> 165000
C41: Dividends | D41: =SUMIFS('Detailed BS'!F:F,'Detailed BS'!$D:$D,$C41) -> -1792102.6 | E41: =SUMIFS('Detailed BS'!G:G,'Detailed BS'!$D:$D,$C41) -> -1554050.7 | F41: =SUMIFS('Detailed BS'!H:H,'Detailed BS'!$D:$D,$C41) -> -905247.85 | G41: =SUMIFS('Detailed BS'!I:I,'Detailed BS'!$D:$D,$C41) -> 0 | H41: =SUMIFS('Detailed BS'!J:J,'Detailed BS'!$D:$D,$C41) -> 37017.44
C42: Retained Earnings | D42: =SUMIFS('Detailed BS'!F:F,'Detailed BS'!$D:$D,$C42) -> 6477387 | E42: =SUMIFS('Detailed BS'!G:G,'Detailed BS'!$D:$D,$C42) -> 4805268.8 | F42: =SUMIFS('Detailed BS'!H:H,'Detailed BS'!$D:$D,$C42) -> 4944293.6 | G42: =SUMIFS('Detailed BS'!I:I,'Detailed BS'!$D:$D,$C42) -> 5164656.3 | H42: =SUMIFS('Detailed BS'!J:J,'Detailed BS'!$D:$D,$C42) -> 5385890.8
C43: Net Income | D43: =SUMIFS('Detailed BS'!F:F,'Detailed BS'!$D:$D,$C43) -> 119984.37 | E43: =SUMIFS('Detailed BS'!G:G,'Detailed BS'!$D:$D,$C43) -> 1556135.5 | F43: =SUMIFS('Detailed BS'!H:H,'Detailed BS'!$D:$D,$C43) -> 1000850.6 | G43: =SUMIFS('Detailed BS'!I:I,'Detailed BS'!$D:$D,$C43) -> 221234.47 | H43: =SUMIFS('Detailed BS'!J:J,'Detailed BS'!$D:$D,$C43) -> 121987.15
B44: Total Equity | D44: =SUM(D40:D43) -> 4970268.8 | E44: =SUM(E40:E43) -> 4972353.6 | F44: =SUM(F40:F43) -> 5204896.4 | G44: =SUM(G40:G43) -> 5550890.7 | H44: =SUM(H40:H43) -> 5709895.3
B46: Total Liabilities & Equity | D46: =D44+D37 -> 5224900.4 | E46: =E44+E37 -> 5580190.9 | F46: =F44+F37 -> 5848168.3 | G46: =G44+G37 -> 5988669.7 | H46: =H44+H37 -> 5977553.8
...

Sheet Mapping>>

Sheet Chart of Accounts
B1: AAC Adjusted EBITDA Analysis
B2: Chart of Accounts
B5: Account Number | C5: Name | D5: KG Mapping | E5: Type
B6: 00-1110-000 | C6: =_xlfn.XLOOKUP(B6,'Sep 2025 BS'!A:A,'Sep 2025 BS'!B:B) -> -Chase - Checking | D6: Cash | E6: Asset
B7: 00-1111-000 | C7: =_xlfn.XLOOKUP(B7,'Sep 2025 BS'!A:A,'Sep 2025 BS'!B:B) -> -Chase - Payroll | D7: Cash | E7: Asset
B8: 00-1112-000 | C8: =_xlfn.XLOOKUP(B8,'Sep 2025 BS'!A:A,'Sep 2025 BS'!B:B) -> -Chase - AR Payments | D8: Cash | E8: Asset
B9: 00-1125-000 | C9: =_xlfn.XLOOKUP(B9,'Sep 2025 BS'!A:A,'Sep 2025 BS'!B:B) -> -Allowance for Doubtful Accounts | D9: Allowance for Doubtful Accounts | E9: Asset
B10: 00-1126-000 | C10: =_xlfn.XLOOKUP(B10,'Sep 2025 BS'!A:A,'Sep 2025 BS'!B:B) -> -Customer Deposits | D10: Customer Depsits | E10: Asset
B11: 00-1127-000 | C11: -A/R - Other | D11: Accounts Receivable | E11: Asset
B12: 00-1140-000 | C12: =_xlfn.XLOOKUP(B12,'Sep 2025 BS'!A:A,'Sep 2025 BS'!B:B) -> -Morgan Stanley | D12: Investments | E12: Asset
B13: 00-1150-000 | C13: Charles Scwab | D13: Investments | E13: Asset
B14: 00-1190-000 | C14: =_xlfn.XLOOKUP(B14,'Sep 2025 BS'!A:A,'Sep 2025 BS'!B:B) -> Petty Cash | D14: Cash | E14: Asset
B15: 00-1210-000 | C15: =_xlfn.XLOOKUP(B15,'Sep 2025 BS'!A:A,'Sep 2025 BS'!B:B) -> -Accounts Receivable | D15: Accounts Receivable | E15: Asset
B16: 00-1310-000 | C16: =_xlfn.XLOOKUP(B16,'Sep 2025 BS'!A:A,'Sep 2025 BS'!B:B) -> -Raw Material | D16: Inventory | E16: Asset
B17: 00-1320-000 | C17: =_xlfn.XLOOKUP(B17,'Sep 2025 BS'!A:A,'Sep 2025 BS'!B:B) -> -W I P | D17: Inventory | E17: Asset
B18: 00-1330-000 | C18: =_xlfn.XLOOKUP(B18,'Sep 2025 BS'!A:A,'Sep 2025 BS'!B:B) -> -Finished Goods | D18: Inventory | E18: Asset
B19: 00-1340-000 | C19: =_xlfn.XLOOKUP(B19,'Sep 2025 BS'!A:A,'Sep 2025 BS'!B:B) -> -Inventory - Inspection | D19: Inventory | E19: Asset
B20: 00-1350-000 | C20: =_xlfn.XLOOKUP(B20,'Sep 2025 BS'!A:A,'Sep 2025 BS'!B:B) -> -Inventory - DMR Pending | D20: Inventory | E20: Asset
B21: 00-1410-000 | C21: =_xlfn.XLOOKUP(B21,'Sep 2025 BS'!A:A,'Sep 2025 BS'!B:B) -> -Land | D21: Land | E21: Asset
B22: 00-1420-000 | C22: =_xlfn.XLOOKUP(B22,'Sep 2025 BS'!A:A,'Sep 2025 BS'!B:B) -> -Building | D22: Building | E22: Asset
B23: 00-1430-000 | C23: =_xlfn.XLOOKUP(B23,'Sep 2025 BS'!A:A,'Sep 2025 BS'!B:B) -> -Leasehold Improvements | D23: Leasehold Improvements | E23: Asset
B24: 00-1440-000 | C24: =_xlfn.XLOOKUP(B24,'Sep 2025 BS'!A:A,'Sep 2025 BS'!B:B) -> -Machinery & Equipment | D24: Machinery & Equipment | E24: Asset
B25: 00-1460-000 | C25: =_xlfn.XLOOKUP(B25,'Sep 2025 BS'!A:A,'Sep 2025 BS'!B:B) -> -Computer Equipment | D25: Computer Equipment | E25: Asset
... B32: 00-1530-000 | C32: =_xlfn.XLOOKUP(B32,'Sep 2025 BS'!A:A,'Sep 2025 BS'!B:B) -> -Prepaid RE Taxes | D32: Prepaid Expenses | E32: Asset
B33: 00-1540-000 | C33: -Prepaid Other | D33: Prepaid Expenses | E33: Asset
B34: 00-1550-000 | C34: =_xlfn.XLOOKUP(B34,'Sep 2025 BS'!A:A,'Sep 2025 BS'!B:B) -> -Advances | D34: Prepaid Expenses | E34: Asset
B35: 00-1560-000 | C35: =_xlfn.XLOOKUP(B35,'Sep 2025 BS'!A:A,'Sep 2025 BS'!B:B) -> -PPD - Trade Show Expenses | D35: Prepaid Expenses | E35: Asset
B36: 00-2110-000 | C36: =_xlfn.XLOOKUP(B36,'Sep 2025 BS'!A:A,'Sep 2025 BS'!B:B) -> -Accounts Payable | D36: Accounts Payable | E36: Liability
B37: 00-2115-000 | C37: =_xlfn.XLOOKUP(B37,'Sep 2025 BS'!A:A,'Sep 2025 BS'!B:B) -> AMEX Payable | D37: Accounts Payable | E37: Liability
B38: 00-2116-000 | C38: -VISA Payable | D38: Accounts Payable | E38: Liability
B39: 00-2120-000 | C39: =_xlfn.XLOOKUP(B39,'Sep 2025 BS'!A:A,'Sep 2025 BS'!B:B) -> -Accrued Purchase Receipts | D39: Accounts Payable | E39: Liability
B40: 00-2230-000 | C40: -401K Payable | D40: Accured Expenses | E40: Liability
B41: 00-2295-000 | C41: =_xlfn.XLOOKUP(B41,'Sep 2025 BS'!A:A,'Sep 2025 BS'!B:B) -> -Lease Payable - Screen Printer | D41: Leases Payable | E41: Liability
B42: 00-2296-000 | C42: =_xlfn.XLOOKUP(B42,'Sep 2025 BS'!A:A,'Sep 2025 BS'!B:B) -> -Lease Payable - Pick and Place | D42: Leases Payable | E42: Liability
B43: 00-2297-000 | C43: =_xlfn.XLOOKUP(B43,'Sep 2025 BS'!A:A,'Sep 2025 BS'!B:B) -> -Lease Payable - Phone System | D43: Leases Payable | E43: Liability
B44: 00-2310-000 | C44: =_xlfn.XLOOKUP(B44,'Sep 2025 BS'!A:A,'Sep 2025 BS'!B:B) -> -Accrued Payroll & Taxes | D44: Accured Expenses | E44: Liability
B45: 00-2340-000 | C45: =_xlfn.XLOOKUP(B45,'Sep 2025 BS'!A:A,'Sep 2025 BS'!B:B) -> -Accrued Expenses | D45: Accured Expenses | E45: Liability
B46: 00-2350-000 | C46: =_xlfn.XLOOKUP(B46,'Sep 2025 BS'!A:A,'Sep 2025 BS'!B:B) -> -Accrued Profit Sharing | D46: Accured Expenses | E46: Liability
B47: 00-3300-000 | C47: Common Stock | D47: Common Stock | E47: Equity
B48: 00-3310-000 | C48: =_xlfn.XLOOKUP(B48,'Sep 2025 BS'!A:A,'Sep 2025 BS'!B:B) -> -Retained Earnings - Distributions | D48: Retained Earnings | E48: Equity
...

Sheet Detailed IS
B1: AAC Adjusted EBITDA Analysis
B2: Detailed IS
B4: Account Number | C4: Name | D4: KG Mapping | E4: Type | F4: 44561 | G4: =EOMONTH(F4,12) -> 44926 | H4: =EOMONTH(G4,12) -> 45291 | I4: =EOMONTH(H4,12) -> 45657 | J4: =EOMONTH(I4,9) -> 45930
B5: 00-5110 | C5: -Product Sales | D5: =_xlfn.XLOOKUP(B5,'Chart of Accounts'!B:B,'Chart of Accounts'!D:D) -> Product Sales | E5: Revenue | F5: =SUMIFS('2021 IS'!C:C,'2021 IS'!A:A,B5) -> 0 | G5: =SUMIFS('2022 IS'!C:C,'2022 IS'!A:A,B5) -> 0 | H5: =SUMIFS('2023 IS'!C:C,'2023 IS'!A:A,B5) -> 0 | I5: =SUMIFS('2024 IS'!C:C,'2024 IS'!A:A,B5) -> 0 | J5: =SUMIFS('2025 IS'!C:C,'2025 IS'!A:A,B5) -> 0
B6: 00-5110-000 | C6: -Product Sales | D6: =_xlfn.XLOOKUP(B6,'Chart of Accounts'!B:B,'Chart of Accounts'!D:D) -> Product Sales | E6: Revenue | F6: =SUMIFS('2021 IS'!C:C,'2021 IS'!A:A,B6) -> 1125166.1 | G6: =SUMIFS('2022 IS'!C:C,'2022 IS'!A:A,B6) -> 515796.36 | H6: =SUMIFS('2023 IS'!C:C,'2023 IS'!A:A,B6) -> 1245336.4 | I6: =SUMIFS('2024 IS'!C:C,'2024 IS'!A:A,B6) -> 937459.54 | J6: =SUMIFS('2025 IS'!C:C,'2025 IS'!A:A,B6) -> 392663.3
B7: 00-5120-000 | C7: -Customer Returns | D7: =_xlfn.XLOOKUP(B7,'Chart of Accounts'!B:B,'Chart of Accounts'!D:D) -> Other Income | E7: Revenue | F7: =SUMIFS('2021 IS'!C:C,'2021 IS'!A:A,B7) -> 0 | G7: =SUMIFS('2022 IS'!C:C,'2022 IS'!A:A,B7) -> 0 | H7: =SUMIFS('2023 IS'!C:C,'2023 IS'!A:A,B7) -> 0 | I7: =SUMIFS('2024 IS'!C:C,'2024 IS'!A:A,B7) -> 0 | J7: =SUMIFS('2025 IS'!C:C,'2025 IS'!A:A,B7) -> 0
B8: 00-5130 | C8: -Customer Credits & Discounts | D8: =_xlfn.XLOOKUP(B8,'Chart of Accounts'!B:B,'Chart of Accounts'!D:D) -> Other Income | E8: Revenue | F8: =SUMIFS('2021 IS'!C:C,'2021 IS'!A:A,B8) -> 0 | G8: =SUMIFS('2022 IS'!C:C,'2022 IS'!A:A,B8) -> 0 | H8: =SUMIFS('2023 IS'!C:C,'2023 IS'!A:A,B8) -> 0 | I8: =SUMIFS('2024 IS'!C:C,'2024 IS'!A:A,B8) -> 0 | J8: =SUMIFS('2025 IS'!C:C,'2025 IS'!A:A,B8) -> 0
B9: 00-5130-000 | C9: -Customer Credits & Discounts | D9: =_xlfn.XLOOKUP(B9,'Chart of Accounts'!B:B,'Chart of Accounts'!D:D) -> Other Income | E9: Revenue | F9: =SUMIFS('2021 IS'!C:C,'2021 IS'!A:A,B9) -> 6300 | G9: =SUMIFS('2022 IS'!C:C,'2022 IS'!A:A,B9) -> 0 | H9: =SUMIFS('2023 IS'!C:C,'2023 IS'!A:A,B9) -> -0.71 | I9: =SUMIFS('2024 IS'!C:C,'2024 IS'!A:A,B9) -> -102 | J9: =SUMIFS('2025 IS'!C:C,'2025 IS'!A:A,B9) -> 0
B10: 00-5190-000 | C10: -Other Customer Charges | D10: =_xlfn.XLOOKUP(B10,'Chart of Accounts'!B:B,'Chart of Accounts'!D:D) -> Other Income | E10: Revenue | F10: =SUMIFS('2021 IS'!C:C,'2021 IS'!A:A,B10) -> 675 | G10: =SUMIFS('2022 IS'!C:C,'2022 IS'!A:A,B10) -> 510 | H10: =SUMIFS('2023 IS'!C:C,'2023 IS'!A:A,B10) -> 5500 | I10: =SUMIFS('2024 IS'!C:C,'2024 IS'!A:A,B10) -> 2300 | J10: =SUMIFS('2025 IS'!C:C,'2025 IS'!A:A,B10) -> 300
B11: 00-5510-000 | C11: -Engineering Services | D11: =_xlfn.XLOOKUP(B11,'Chart of Accounts'!B:B,'Chart of Accounts'!D:D) -> Engineering Services | E11: Revenue | F11: =SUMIFS('2021 IS'!C:C,'2021 IS'!A:A,B11) -> 0 | G11: =SUMIFS('2022 IS'!C:C,'2022 IS'!A:A,B11) -> 0 | H11: =SUMIFS('2023 IS'!C:C,'2023 IS'!A:A,B11) -> 0 | I11: =SUMIFS('2024 IS'!C:C,'2024 IS'!A:A,B11) -> 364232 | J11: =SUMIFS('2025 IS'!C:C,'2025 IS'!A:A,B11) -> 0
B12: -5130 | C12: -Customer Credits & Discounts | D12: =_xlfn.XLOOKUP(B12,'Chart of Accounts'!B:B,'Chart of Accounts'!D:D) -> Other Income | E12: Revenue | F12: =SUMIFS('2021 IS'!C:C,'2021 IS'!A:A,B12) -> 0 | G12: =SUMIFS('2022 IS'!C:C,'2022 IS'!A:A,B12) -> 0 | H12: =SUMIFS('2023 IS'!C:C,'2023 IS'!A:A,B12) -> 0 | I12: =SUMIFS('2024 IS'!C:C,'2024 IS'!A:A,B12) -> 0 | J12: =SUMIFS('2025 IS'!C:C,'2025 IS'!A:A,B12) -> 0
B13: 00-6110-000 | C13: -Material - Product Sales | D13: =_xlfn.XLOOKUP(B13,'Chart of Accounts'!B:B,'Chart of Accounts'!D:D) -> Materials | E13: Cost of Goods Sold | F13: =SUMIFS('2021 IS'!C:C,'2021 IS'!A:A,B13) -> 189511.51 | G13: =SUMIFS('2022 IS'!C:C,'2022 IS'!A:A,B13) -> 439243.06 | H13: =SUMIFS('2023 IS'!C:C,'2023 IS'!A:A,B13) -> 76639.33 | I13: =SUMIFS('2024 IS'!C:C,'2024 IS'!A:A,B13) -> -209294.31 | J13: =SUMIFS('2025 IS'!C:C,'2025 IS'!A:A,B13) -> 44925.16
B14: 00-6120-000 | C14: -Labor - Product Sales | D14: =_xlfn.XLOOKUP(B14,'Chart of Accounts'!B:B,'Chart of Accounts'!D:D) -> Salaries and Wages - Direct | E14: Cost of Goods Sold | F14: =SUMIFS('2021 IS'!C:C,'2021 IS'!A:A,B14) -> 29407.01 | G14: =SUMIFS('2022 IS'!C:C,'2022 IS'!A:A,B14) -> 30516.8 | H14: =SUMIFS('2023 IS'!C:C,'2023 IS'!A:A,B14) -> 52120.78 | I14: =SUMIFS('2024 IS'!C:C,'2024 IS'!A:A,B14) -> 29716.65 | J14: =SUMIFS('2025 IS'!C:C,'2025 IS'!A:A,B14) -> 35372.67
B15: 00-6130-000 | C15: -Overhead - Product Sales | D15: =_xlfn.XLOOKUP(B15,'Chart of Accounts'!B:B,'Chart of Accounts'!D:D) -> Overhead | E15: Cost of Goods Sold | F15: =SUMIFS('2021 IS'!C:C,'2021 IS'!A:A,B15) -> 44154.87 | G15: =SUMIFS('2022 IS'!C:C,'2022 IS'!A:A,B15) -> 45772.59 | H15: =SUMIFS('2023 IS'!C:C,'2023 IS'!A:A,B15) -> 78436.09 | I15: =SUMIFS('2024 IS'!C:C,'2024 IS'!A:A,B15) -> 44657.41 | J15: =SUMIFS('2025 IS'!C:C,'2025 IS'!A:A,B15) -> 126933.91
B16: 00-6140-000 | C16: -Outside Services - Product Sales | D16: =_xlfn.XLOOKUP(B16,'Chart of Accounts'!B:B,'Chart of Accounts'!D:D) -> Outside Services | E16: Cost of Goods Sold | F16: =SUMIFS('2021 IS'!C:C,'2021 IS'!A:A,B16) -> 13578.35 | G16: =SUMIFS('2022 IS'!C:C,'2022 IS'!A:A,B16) -> 6833.06 | H16: =SUMIFS('2023 IS'!C:C,'2023 IS'!A:A,B16) -> 22493.41 | I16: =SUMIFS('2024 IS'!C:C,'2024 IS'!A:A,B16) -> 9512.15 | J16: =SUMIFS('2025 IS'!C:C,'2025 IS'!A:A,B16) -> 16237.04
... B166: 00-9995-000 | C166: -Corporate Taxes - State | D166: =_xlfn.XLOOKUP(B166,'Chart of Accounts'!B:B,'Chart of Accounts'!D:D) -> Corporate Taxes | E166: Taxes | F166: =SUMIFS('2021 IS'!C:C,'2021 IS'!A:A,B166) -> 0 | G166: =SUMIFS('2022 IS'!C:C,'2022 IS'!A:A,B166) -> 166364.31 | H166: =SUMIFS('2023 IS'!C:C,'2023 IS'!A:A,B166) -> 26209.75 | I166: =SUMIFS('2024 IS'!C:C,'2024 IS'!A:A,B166) -> 6209.75 | J166: =SUMIFS('2025 IS'!C:C,'2025 IS'!A:A,B166) -> 0

Sheet Detailed BS
B1: AAC Adjusted EBITDA Analysis
B2: Detailed BS
B4: Account Number | C4: Name | D4: KG Mapping | E4: Type | F4: 44561 | G4: =EOMONTH(F4,12) -> 44926 | H4: =EOMONTH(G4,12) -> 45291 | I4: =EOMONTH(H4,12) -> 45657 | J4: =EOMONTH(I4,9) -> 45930
B5: 00-1110-000 | C5: =_xlfn.XLOOKUP(B5,'Chart of Accounts'!B:B,'Chart of Accounts'!C:C) -> -Chase - Checking | D5: =_xlfn.XLOOKUP(B5,'Chart of Accounts'!B:B,'Chart of Accounts'!D:D) -> Cash | E5: Asset | F5: =SUMIFS('2022 BS'!D:D,'2022 BS'!A:A,$B5) -> 968363.21 | G5: =SUMIFS('2022 BS'!C:C,'2022 BS'!A:A,B5) -> 2210695.4 | H5: =SUMIFS('2023 BS'!C:C,'2023 BS'!A:A,B5) -> 1598672.4 | I5: =SUMIFS('2024 BS'!C:C,'2024 BS'!A:A,B5) -> 533754.04 | J5: =SUMIFS('Sep 2025 BS'!C:C,'Sep 2025 BS'!A:A,B5) -> 382938.75
B6: 00-1111-000 | C6: =_xlfn.XLOOKUP(B6,'Chart of Accounts'!B:B,'Chart of Accounts'!C:C) -> -Chase - Payroll | D6: =_xlfn.XLOOKUP(B6,'Chart of Accounts'!B:B,'Chart of Accounts'!D:D) -> Cash | E6: Asset | F6: =SUMIFS('2022 BS'!D:D,'2022 BS'!A:A,$B6) -> 223606.31 | G6: =SUMIFS('2022 BS'!C:C,'2022 BS'!A:A,B6) -> 185561.08 | H6: =SUMIFS('2023 BS'!C:C,'2023 BS'!A:A,B6) -> 14095.12 | I6: =SUMIFS('2024 BS'!C:C,'2024 BS'!A:A,B6) -> 131962.6 | J6: =SUMIFS('Sep 2025 BS'!C:C,'Sep 2025 BS'!A:A,B6) -> 116237.34
B7: 00-1112-000 | C7: =_xlfn.XLOOKUP(B7,'Chart of Accounts'!B:B,'Chart of Accounts'!C:C) -> -Chase - AR Payments | D7: =_xlfn.XLOOKUP(B7,'Chart of Accounts'!B:B,'Chart of Accounts'!D:D) -> Cash | E7: Asset | F7: =SUMIFS('2022 BS'!D:D,'2022 BS'!A:A,$B7) -> 6738.44 | G7: =SUMIFS('2022 BS'!C:C,'2022 BS'!A:A,B7) -> 2000 | H7: =SUMIFS('2023 BS'!C:C,'2023 BS'!A:A,B7) -> 2000 | I7: =SUMIFS('2024 BS'!C:C,'2024 BS'!A:A,B7) -> 360982.28 | J7: =SUMIFS('Sep 2025 BS'!C:C,'Sep 2025 BS'!A:A,B7) -> 81142.26
B8: 00-1125-000 | C8: =_xlfn.XLOOKUP(B8,'Chart of Accounts'!B:B,'Chart of Accounts'!C:C) -> -Allowance for Doubtful Accounts | D8: =_xlfn.XLOOKUP(B8,'Chart of Accounts'!B:B,'Chart of Accounts'!D:D) -> Allowance for Doubtful Accounts | E8: Asset | F8: =SUMIFS('2022 BS'!D:D,'2022 BS'!A:A,$B8) -> -15130.57 | G8: =SUMIFS('2022 BS'!C:C,'2022 BS'!A:A,B8) -> -15130.57 | H8: =SUMIFS('2023 BS'!C:C,'2023 BS'!A:A,B8) -> -15130.57 | I8: =SUMIFS('2024 BS'!C:C,'2024 BS'!A:A,B8) -> -15130.57 | J8: =SUMIFS('Sep 2025 BS'!C:C,'Sep 2025 BS'!A:A,B8) -> -15130.57
B9: 00-1126-000 | C9: =_xlfn.XLOOKUP(B9,'Chart of Accounts'!B:B,'Chart of Accounts'!C:C) -> -Customer Deposits | D9: =_xlfn.XLOOKUP(B9,'Chart of Accounts'!B:B,'Chart of Accounts'!D:D) -> Customer Depsits | E9: Asset | F9: =SUMIFS('2022 BS'!D:D,'2022 BS'!A:A,$B9) -> -24542.41 | G9: =SUMIFS('2022 BS'!C:C,'2022 BS'!A:A,B9) -> -18599.3 | H9: =SUMIFS('2023 BS'!C:C,'2023 BS'!A:A,B9) -> -28159.91 | I9: =SUMIFS('2024 BS'!C:C,'2024 BS'!A:A,B9) -> -31574.74 | J9: =SUMIFS('Sep 2025 BS'!C:C,'Sep 2025 BS'!A:A,B9) -> -19542.76
B10: 00-1127-000 | C10: =_xlfn.XLOOKUP(B10,'Chart of Accounts'!B:B,'Chart of Accounts'!C:C) -> -A/R - Other | D10: =_xlfn.XLOOKUP(B10,'Chart of Accounts'!B:B,'Chart of Accounts'!D:D) -> Accounts Receivable | E10: Asset | F10: =SUMIFS('2022 BS'!D:D,'2022 BS'!A:A,$B10) -> 0 | G10: =SUMIFS('2022 BS'!C:C,'2022 BS'!A:A,B10) -> 0 | H10: =SUMIFS('2023 BS'!C:C,'2023 BS'!A:A,B10) -> 0 | I10: =SUMIFS('2024 BS'!C:C,'2024 BS'!A:A,B10) -> 6098.5 | J10: =SUMIFS('Sep 2025 BS'!C:C,'Sep 2025 BS'!A:A,B10) -> 0
B11: 00-1140-000 | C11: =_xlfn.XLOOKUP(B11,'Chart of Accounts'!B:B,'Chart of Accounts'!C:C) -> -Morgan Stanley | D11: =_xlfn.XLOOKUP(B11,'Chart of Accounts'!B:B,'Chart of Accounts'!D:D) -> Investments | E11: Asset | F11: =SUMIFS('2022 BS'!D:D,'2022 BS'!A:A,$B11) -> 579372.3 | G11: =SUMIFS('2022 BS'!C:C,'2022 BS'!A:A,B11) -> 405784.26 | H11: =SUMIFS('2023 BS'!C:C,'2023 BS'!A:A,B11) -> 420307.73 | I11: =SUMIFS('2024 BS'!C:C,'2024 BS'!A:A,B11) -> 815111.44 | J11: =SUMIFS('Sep 2025 BS'!C:C,'Sep 2025 BS'!A:A,B11) -> 1723864.4
B12: 00-1150-000 | C12: =_xlfn.XLOOKUP(B12,'Chart of Accounts'!B:B,'Chart of Accounts'!C:C) -> Charles Scwab | D12: =_xlfn.XLOOKUP(B12,'Chart of Accounts'!B:B,'Chart of Accounts'!D:D) -> Investments | E12: Asset | F12: =SUMIFS('2022 BS'!D:D,'2022 BS'!A:A,$B12) -> 5785.03 | G12: =SUMIFS('2022 BS'!C:C,'2022 BS'!A:A,B12) -> 0 | H12: =SUMIFS('2023 BS'!C:C,'2023 BS'!A:A,B12) -> 0 | I12: =SUMIFS('2024 BS'!C:C,'2024 BS'!A:A,B12) -> 0 | J12: =SUMIFS('Sep 2025 BS'!C:C,'Sep 2025 BS'!A:A,B12) -> 0
B13: 00-1190-000 | C13: =_xlfn.XLOOKUP(B13,'Chart of Accounts'!B:B,'Chart of Accounts'!C:C) -> Petty Cash | D13: =_xlfn.XLOOKUP(B13,'Chart of Accounts'!B:B,'Chart of Accounts'!D:D) -> Cash | E13: Asset | F13: =SUMIFS('2022 BS'!D:D,'2022 BS'!A:A,$B13) -> 500 | G13: =SUMIFS('2022 BS'!C:C,'2022 BS'!A:A,B13) -> 500 | H13: =SUMIFS('2023 BS'!C:C,'2023 BS'!A:A,B13) -> 500 | I13: =SUMIFS('2024 BS'!C:C,'2024 BS'!A:A,B13) -> 0 | J13: =SUMIFS('Sep 2025 BS'!C:C,'Sep 2025 BS'!A:A,B13) -> 0
B14: 00-1210-000 | C14: =_xlfn.XLOOKUP(B14,'Chart of Accounts'!B:B,'Chart of Accounts'!C:C) -> -Accounts Receivable | D14: =_xlfn.XLOOKUP(B14,'Chart of Accounts'!B:B,'Chart of Accounts'!D:D) -> Accounts Receivable | E14: Asset | F14: =SUMIFS('2022 BS'!D:D,'2022 BS'!A:A,$B14) -> 1105726.3 | G14: =SUMIFS('2022 BS'!C:C,'2022 BS'!A:A,B14) -> 525775.94 | H14: =SUMIFS('2023 BS'!C:C,'2023 BS'!A:A,B14) -> 1262808.8 | I14: =SUMIFS('2024 BS'!C:C,'2024 BS'!A:A,B14) -> 1141704.1 | J14: =SUMIFS('Sep 2025 BS'!C:C,'Sep 2025 BS'!A:A,B14) -> 437988.79
B15: 00-1310-000 | C15: =_xlfn.XLOOKUP(B15,'Chart of Accounts'!B:B,'Chart of Accounts'!C:C) -> -Raw Material | D15: =_xlfn.XLOOKUP(B15,'Chart of Accounts'!B:B,'Chart of Accounts'!D:D) -> Inventory | E15: Asset | F15: =SUMIFS('2022 BS'!D:D,'2022 BS'!A:A,$B15) -> 1415642.8 | G15: =SUMIFS('2022 BS'!C:C,'2022 BS'!A:A,B15) -> 1444746.5 | H15: =SUMIFS('2023 BS'!C:C,'2023 BS'!A:A,B15) -> 1624790.3 | I15: =SUMIFS('2024 BS'!C:C,'2024 BS'!A:A,B15) -> 2020749.1 | J15: =SUMIFS('Sep 2025 BS'!C:C,'Sep 2025 BS'!A:A,B15) -> 2080333.4
B16: 00-1320-000 | C16: =_xlfn.XLOOKUP(B16,'Chart of Accounts'!B:B,'Chart of Accounts'!C:C) -> -W I P | D16: =_xlfn.XLOOKUP(B16,'Chart of Accounts'!B:B,'Chart of Accounts'!D:D) -> Inventory | E16: Asset | F16: =SUMIFS('2022 BS'!D:D,'2022 BS'!A:A,$B16) -> 375815.92 | G16: =SUMIFS('2022 BS'!C:C,'2022 BS'!A:A,B16) -> 379024.97 | H16: =SUMIFS('2023 BS'!C:C,'2023 BS'!A:A,B16) -> 323109.05 | I16: =SUMIFS('2024 BS'!C:C,'2024 BS'!A:A,B16) -> 562533.14 | J16: =SUMIFS('Sep 2025 BS'!C:C,'Sep 2025 BS'!A:A,B16) -> 741600.29
... B46: 00-3310-000 | C46: =_xlfn.XLOOKUP(B46,'Chart of Accounts'!B:B,'Chart of Accounts'!C:C) -> -Retained Earnings - Distributions | D46: =_xlfn.XLOOKUP(B46,'Chart of Accounts'!B:B,'Chart of Accounts'!D:D) -> Retained Earnings | E46: Equity | F46: =SUMIFS('2022 BS'!D:D,'2022 BS'!A:A,$B46) -> -14380363 | G46: =SUMIFS('2022 BS'!C:C,'2022 BS'!A:A,B46) -> -16172466 | H46: =SUMIFS('2023 BS'!C:C,'2023 BS'!A:A,B46) -> -17589577 | I46: =SUMIFS('2024 BS'!C:C,'2024 BS'!A:A,B46) -> -18370065 | J46: =SUMIFS('Sep 2025 BS'!C:C,'Sep 2025 BS'!A:A,B46) -> -18370065
B47: 00-3300-000 | C47: Common Stock | D47: =_xlfn.XLOOKUP(B47,'Chart of Accounts'!B:B,'Chart of Accounts'!D:D) -> Common Stock | E47: Equity | F47: =SUMIFS('2022 BS'!D:D,'2022 BS'!A:A,$B47) -> 165000 | G47: =SUMIFS('2022 BS'!C:C,'2022 BS'!A:A,B47) -> 165000 | H47: =SUMIFS('2023 BS'!C:C,'2023 BS'!A:A,B47) -> 165000 | I47: =SUMIFS('2024 BS'!C:C,'2024 BS'!A:A,B47) -> 165000 | J47: =SUMIFS('Sep 2025 BS'!C:C,'Sep 2025 BS'!A:A,B47) -> 165000
B48: 00-3320-000 | C48: Tax Payments-Current Year | D48: =_xlfn.XLOOKUP(B48,'Chart of Accounts'!B:B,'Chart of Accounts'!D:D) -> Dividends | E48: Equity | F48: =SUMIFS('2022 BS'!D:D,'2022 BS'!A:A,$B48) -> -871770 | G48: =SUMIFS('2022 BS'!C:C,'2022 BS'!A:A,B48) -> -1181600 | H48: =SUMIFS('2023 BS'!C:C,'2023 BS'!A:A,B48) -> -170000 | I48: =SUMIFS('2024 BS'!C:C,'2024 BS'!A:A,B48) -> 0 | J48: =SUMIFS('Sep 2025 BS'!C:C,'Sep 2025 BS'!A:A,B48) -> 37017.44
B49: 00-3330-000 | C49: Distributions-Current Year | D49: =_xlfn.XLOOKUP(B49,'Chart of Accounts'!B:B,'Chart of Accounts'!D:D) -> Dividends | E49: Equity | F49: =SUMIFS('2022 BS'!D:D,'2022 BS'!A:A,$B49) -> -920332.57 | G49: =SUMIFS('2022 BS'!C:C,'2022 BS'!A:A,B49) -> -372450.74 | H49: =SUMIFS('2023 BS'!C:C,'2023 BS'!A:A,B49) -> -735247.85 | I49: =SUMIFS('2024 BS'!C:C,'2024 BS'!A:A,B49) -> 0 | J49: =SUMIFS('Sep 2025 BS'!C:C,'Sep 2025 BS'!A:A,B49) -> 0
B50: 00-3340-000 | C50: Retained Earnings-Prior Years | D50: =_xlfn.XLOOKUP(B50,'Chart of Accounts'!B:B,'Chart of Accounts'!D:D) -> Retained Earnings | E50: Equity | F50: =SUMIFS('2022 BS'!D:D,'2022 BS'!A:A,$B50) -> 20857750 | G50: =SUMIFS('2022 BS'!C:C,'2022 BS'!A:A,B50) -> 20977735 | H50: =SUMIFS('2023 BS'!C:C,'2023 BS'!A:A,B50) -> 22533870 | I50: =SUMIFS('2024 BS'!C:C,'2024 BS'!A:A,B50) -> 23534721 | J50: =SUMIFS('Sep 2025 BS'!C:C,'Sep 2025 BS'!A:A,B50) -> 23755955
B51: 00-3350-000 | C51: Current Year - Profit ( Loss ) | D51: =_xlfn.XLOOKUP(B51,'Chart of Accounts'!B:B,'Chart of Accounts'!D:D) -> Net Income | E51: Equity | F51: =SUMIFS('2022 BS'!D:D,'2022 BS'!A:A,$B51) -> 119984.37 | G51: =SUMIFS('2022 BS'!C:C,'2022 BS'!A:A,B51) -> 1556135.5 | H51: =SUMIFS('2023 BS'!C:C,'2023 BS'!A:A,B51) -> 1000850.6 | I51: =SUMIFS('2024 BS'!C:C,'2024 BS'!A:A,B51) -> 221234.47 | J51: =SUMIFS('Sep 2025 BS'!C:C,'Sep 2025 BS'!A:A,B51) -> 121987.15

Sheet Source Documents >>>

Sheet EBITDA
A1: American Aerospace Controls, Inc.
A2: Adjusted EBITDA Summaries
A4: 2021-2025
D5: 2021 | E5: 2022 | F5: 2023 | G5: 2024 | H5: 2025 YTD
H6: Sept
A7: Net Income per Books | D7: 119984 | E7: 1556136 | F7: 1000851 | G7: 220635 | H7: 121987
A9: Depreciation & Amortization | D9: =10500+59499 -> 69999 | E9: =11794+66834 -> 78628 | F9: 168273 | G9: =114510+20208 -> 134718 | H9: 17000
A10: Interest Expense | D10: 0 | E10: 0 | F10: 13668 | G10: 5890 | H10: 9986
A11: Taxes | D11: 25 | E11: 0 | F11: 30767 | G11: 80165 | H11: 0
A12: Fed Employee Tax Credits | D12: -4611 | E12: 0 | F12: 0 | G12: 0 | H12: 0
A13: Investment (income) loss | D13: -23926 | E13: =-19566-92360 -> -111926 | F13: -14523 | G13: =-17677+35311 -> 17634 | H13: =-41956-88475 -> -130431
B15: Book EBITDA | D15: =SUM(D7:D14) -> 161471 | E15: =SUM(E7:E14) -> 1522838 | F15: =SUM(F7:F14) -> 1199036 | G15: =SUM(G7:G14) -> 459042 | H15: =SUM(H7:H14) -> 18542
A17: Adjustments:
B18: Officer's Salary | D18: 355769 | E18: 364361 | F18: 171000 | G18: 100000 | H18: 75000
B19: Directors Fees | D19: 180693 | E19: 180000 | F19: 224000 | G19: 240000 | H19: 178846
B20: Dennis PA | D20: 15000 | E20: 0 | F20: 0 | G20: 0 | H20: 0
B21: Prof/Cons Fees | D21: =+'Prof Fees'!C8 -> 10580 | E21: =+'Prof Fees'!C20 -> 28054 | F21: =+'Prof Fees'!C35 -> 31288 | G21: =+'Prof Fees'!C44 -> 53880 | H21: =+'Prof Fees'!C56 -> 86402
B22: Acctg Fees | D22: 0 | E22: =+'Prof Fees'!G20 -> 37000 | F22: =+'Prof Fees'!G35 -> 45000 | G22: 0 | H22: 0
B23: MFG Variance | D23: 0 | E23: 0 | F23: 0 | G23: =-H23 -> -265500 | H23: 265500
B24: Staff Cash Bonuses | D24: 40000 | E24: 40000 | F24: 40000 | G24: 40000 | H24: 40000
B25: Net Adjustments | D25: =SUM(D18:D24) -> 602042 | E25: =SUM(E18:E24) -> 649415 | F25: =SUM(F18:F24) -> 511288 | G25: =SUM(G18:G24) -> 168380 | H25: =SUM(H18:H24) -> 645748
B27: Adjusted EBITDA | D27: =+D15+D25 -> 763513 | E27: =+E15+E25 -> 2172253 | F27: =+F15+F25 -> 1710324 | G27: =+G15+G25 -> 627422 | H27: =+H15+H25 -> 664290

Sheet Prof Fees
A1: AAC
A2: Consulting Fees - Non recurring
A4: Date | B4: Payee | C4: Amount
A5: 44561 | B5: Farrell Fritz | C5: 9480
A6: 44408 | B6: Ross Rizley | C6: 1100
C8: =SUM(C5:C7) -> 10580
A10: 44798 | B10: Farrell Fritz | C10: 11414 | E10: 44726 | F10: Jay Gelbein | G10: 9000
A11: 44706 | B11: Sharon Hairston | C11: 1920 | E11: 44754 | F11: Jay Gelbein | G11: 4000
A12: 44741 | B12: Sharon Hairston | C12: 2560 | E12: 44764 | F12: Jay Gelbein | G12: 4000
A13: 44771 | B13: Sharon Hairston | C13: 1920 | E13: 44797 | F13: Jay Gelbein | G13: 4000
A14: 44811 | B14: Sharon Hairston | C14: 3200 | E14: 44826 | F14: Jay Gelbein | G14: 4000
A15: 44837 | B15: Sharon Hairston | C15: 1920 | E15: 44859 | F15: Jay Gelbein | G15: 4000
A16: 44861 | B16: Sharon Hairston | C16: 2560 | E16: 44883 | F16: Jay Gelbein | G16: 4000
A17: 44896 | B17: Sharon Hairston | C17: 1920 | E17: 44900 | F17: Jay Gelbein | G17: 4000
A18: 44914 | B18: Sharon Hairston | C18: 640
C20: =SUM(C10:C19) -> 28054 | G20: =SUM(G10:G19) -> 37000
A22: 44951 | B22: Sharon Hairston | C22: 1920 | E22: 44938 | F22: Jay Gelbein | G22: 9000
A23: 44980 | B23: Sharon Hairston | C23: 2560 | E23: 44971 | F23: Jay Gelbein | G23: 4000
A24: 45015 | B24: Sharon Hairston | C24: 2560 | E24: 44998 | F24: Jay Gelbein | G24: 4000
A25: 45042 | B25: Sharon Hairston | C25: 2560 | E25: 45027 | F25: Jay Gelbein | G25: 4000
A26: 45077 | B26: Sharon Hairston | C26: 2560 | E26: 45055 | F26: Jay Gelbein | G26: 4000
A27: 45093 | B27: Sharon Hairston | C27: 1280 | E27: 45083 | F27: Jay Gelbein | G27: 4000
A28: 45127 | B28: Sharon Hairston | C28: 640 | E28: 45124 | F28: Jay Gelbein | G28: 4000
A29: 45140 | B29: Sharon Hairston | C29: 640 | E29: 45162 | F29: Jay Gelbein | G29: 4000
A30: 45167 | B30: Sharon Hairston | C30: 640 | E30: 45183 | F30: Jay Gelbein | G30: 4000
A31: 45189 | B31: Sharon Hairston | C31: 640 | E31: 45211 | F31: Jay Gelbein | G31: 4000
A32: 45244 | B32: Farrell Fritz | C32: 12358
A33: 45291 | B33: Farrell Fritz | C33: 2930
C35: =SUM(C22:C34) -> 31288 | G35: =SUM(G22:G34) -> 45000
A37: 45421 | B37: Randstad | C37: 10400
A38: 45497 | B38: Randstad | C38: 17680
A39: 45523 | B39: Randstad | C39: 10400
A40: 45590 | B40: JG Lawyer | C40: 2500
A41: 45657 | B41: Farrell Fritz | C41: 7039
A42: 45657 | B42: Farrell Fritz | C42: 5861
C44: =SUM(C37:C43) -> 53880
A46: 45716 | B46: A Abramotwitz | C46: 5955
A47: 45747 | B47: A Abramotwitz | C47: 6975
A48: 45856 | B48: A Abramotwitz | C48: 14493
A49: 45890 | B49: CM Law | C49: 1283
...

Sheet 2021 IS
A1: Account | B1: Description | C1: Current Period | D1: Current Period | E1: Variance | F1: Current YTD | G1: YTD | H1: Variance
D2: Last Year | G2: Last Year
B3: REVENUES
A4: 00-5110 | B4: -Product Sales | C4: 0 | D4: 0 | E4: 0 | F4: 0 | G4: 0 | H4: 0
A5: 00-5110-000 | B5: -Product Sales | C5: 1125166.1 | D5: 1092810.7 | E5: 32355.45 | F5: 6435117.2 | G5: 9491342.2 | H5: -3056224.9
A6: 00-5120-000 | B6: -Customer Returns | C6: 0 | D6: 0 | E6: 0 | F6: 0 | G6: -12600 | H6: 12600
A7: 00-5130 | B7: -Customer Credits & Discounts | C7: 0 | D7: 0 | E7: 0 | F7: 0 | G7: 0 | H7: 0
A8: 00-5130-000 | B8: -Customer Credits & Discounts | C8: 6300 | D8: -0.58 | E8: 6300.58 | F8: -5.7 | G8: 1030.56 | H8: -1036.26
A9: 00-5190-000 | B9: -Other Customer Charges | C9: 675 | D9: 2150 | E9: -1475 | F9: 4473.12 | G9: 9567.66 | H9: -5094.54
A10: 00-5510-000 | B10: -Engineering Services | C10: 0 | D10: 0 | E10: 0 | F10: 0 | G10: 0 | H10: 0
A11: -5130 | B11: -Customer Credits & Discounts | C11: 0 | D11: 0 | E11: 0 | F11: 0 | G11: 0 | H11: 0
B12: Total Revenues | C12: 1132141.1 | D12: 1094960.1 | E12: 37181.03 | F12: 6439584.7 | G12: 9489340.4 | H12: -3049755.7
B13: .
B14: COST OF GOODS SOLD
A15: 00-6110-000 | B15: -Material - Product Sales | C15: 189511.51 | D15: 140609.27 | E15: 48902.24 | F15: 718236.62 | G15: 922018.07 | H15: -203781.45
A16: 00-6120-000 | B16: -Labor - Product Sales | C16: 29407.01 | D16: 38794.3 | E16: -9387.29 | F16: 258832.28 | G16: 360065.31 | H16: -101233.03
A17: 00-6130-000 | B17: -Overhead - Product Sales | C17: 44154.87 | D17: 48296.26 | E17: -4141.39 | F17: 389969.4 | G17: 538794.14 | H17: -148824.74
A18: 00-6140-000 | B18: -Outside Services - Product Sales | C18: 13578.35 | D18: 18919.22 | E18: -5340.87 | F18: 100914.86 | G18: 141172.95 | H18: -40258.09
A19: 00-6145-000 | B19: -Non-Recurring Engineering Costs | C19: 0 | D19: 0 | E19: 0 | F19: 0 | G19: 0 | H19: 0
A20: 00-6150-000 | B20: -Cost of Returns | C20: -356.64 | D20: -632.68 | E20: 276.04 | F20: -4234.42 | G20: -11735.79 | H20: 7501.37
A21: 00-6160-000 | B21: -MFG Variance | C21: 42577.59 | D21: 674.15 | E21: 41903.44 | F21: 60556.48 | G21: 44044.61 | H21: 16511.87
A22: 00-6190-000 | B22: -DMR - COGS | C22: 3004.8 | D22: 78.65 | E22: 2926.15 | F22: 7268.77 | G22: 3529.55 | H22: 3739.22
